Workbook

Sheet ordinary普货
A1: Weifang Yipin Pet Articles Co.,Ltd
A2: ADD: R 301Q, Building 1, Shengshi Haoting Huijingyuan, No. 1999 Wenhua Road, Kuiwen District, Weifang City, Shandong Province,China
A3: yeeaquarium@chongujia.com
A4: INVOICE
A5: Customer Info | G5: Order Info
A6: EXW 客户唛头：Umg Hussein Bassem /Jaafar 07716666543 仓库地址:广东省佛山市南海区里水胜利五一村电台路北3号(自编:8座101) 联系方式:13202011126，李先生 / 136 68976856, Musa 收货时间:周一至周六10:00-18:00 | G6: Invoice No.: 202601050235 Invoice Date: 2026-01-05 Sales Rep: Tina Tong
A7: ORDER 1 （ordinary goods）普货
A8: Item No. | B8: Picture | C8: Business Code | D8: Model | E8: Chinese Name | F8: English Name | G8: Price | H8: QTY | I8: Amount | J8: Remark
G9: （USD） | H9: (PCS) | I9: （USD）
A10: 1 | C10: 1.5.1.7 | D10: YEE-3006 | E10: 50W纯钢加热棒 YSH-50 | F10: 50W pure steel heating rod YSH-50 | G10: 2.4788732 | H10: 8 | I10: =G10*H10 -> 19.830986
A11: 2 | C11: 1.5.1.8 | D11: YEE-3007 | E11: 100W纯钢加热棒 YSH-100 | F11: 100W pure steel heating rod YSH-100 | G11: 2.5633803 | H11: 8 | I11: =G11*H11 -> 20.507042
A12: 3 | C12: 1.5.1.9 | D12: YEE-3008 | E12: 200W纯钢加热棒 YSH-200 | F12: 200W pure steel heating rod YSH-200 | G12: 2.5774648 | H12: 8 | I12: =G12*H12 -> 20.619718
A13: 4 | C13: C4-1432-1 | D13: C4-1432 | E13: Yee意牌水族皓源石英加热棒 100W | F13: Yee brand aquarium quartz heating rod, 100W | G13: 9.76 | H13: 1 | I13: =G13*H13 -> 9.76
A14: 5 | C14: C4-1103-4 | D14: C4-1103 | E14: YEE黑武士加热棒 100W | F14: YEE Black Warrior Heater 100W | G14: 3.5211268 | H14: 5 | I14: =G14*H14 -> 17.605634
A15: 6 | C15: 03326 | D15: YTZ-300 | E15: 小白单孔氧气泵3W（不可调）YTZ-300 | F15: Xiaobai single-hole oxygen pump 3W (non-adjustable) YTZ-300 | G15: 1.1690141 | H15: 3 | I15: 3.51
A16: 7 | C16: 07154 | D16: YGG-135 | E16: YEE 50mm 球形矿物质气泡扩散器 | F16: YEE 50mm Ball Mineral Bubble Diffuser | G16: 1.56 | H16: 15 | I16: 23.4
A17: 8 | C17: C5-1144-1a | D17: C5-1144 | E17: 加强版1.5米/加厚加长 | F17: Enhanced version 1.5 meters/thickened and lengthened | G17: 0.36619718 | H17: 10 | I17: 3.66
A18: 9 | C18: 1.8.3.2 | D18: YEE-3621 | E18: 【加厚气囊 经久耐用】1.7米 | F18: 【Thickened airbag for durability】1.7 meters | G18: 0.91549296 | H18: 10 | I18: 9.15
A19: 10 | C19: C4-1117-1 | D19: C4-1117 | E19: 高配30W 低水位 | F19: High configuration 30W low water level | G19: 8.2816901 | H19: 5 | I19: 41.41
A20: 11 | C20: C4-1008-1 | D20: C4-1008 | E20: 悬浮隔离盒大号 | F20: Large suspended isolation box | G20: 2.6760563 | H20: 8 | I20: 21.41
A21: 12 | C21: 02517 | D21: YSL-506 | E21: 大号气动孵化盒（双房） | F21: Large pneumatic incubator (double room) | G21: 0.99 | H21: 5 | I21: 4.95
A22: 13 | C22: 02771 | D22: YKL-018 | E22: 亚克力培养箱 20*10*10 | F22: Acrylic incubator 20*10*10 | G22: 2.86 | H22: 4 | I22: 11.44
A23: 14 | C23: 05617a | D23: YLL-087 | E23: （蓝色）新升级6D 过滤棉 50*40 两片装 | F23: (Blue) New upgraded 6D filter cotton 50*40 two pieces | G23: 3.0422535 | H23: 4 | I23: 12.17
A24: 15 | C24: 07116 | D24: YFF-042 | E24: 纳米培养环混合装 | F24: Nano Culture Ring Mixed Pack | G24: 1.31 | H24: 8 | I24: 10.48
A25: 16 | C25: 17699a | D25: YAA-009. | E25: 高能量培菌砖 | F25: High energy culture bricks | G25: 0.83 | H25: 5 | I25: 4.15
A26: 17 | C26: 11578 | D26: NYH-006 | E26: Nepall 3D曲奇滤材 500g | F26: 3D filter material | G26: 1.67 | H26: 6 | I26: 10.02
A27: 18 | C27: 71934 | D27: YLC-410 | E27: 十六合一滤材 2.5kg | F27: 16-in-1 filter material 2.5kg | G27: 2.6056338 | H27: 5 | I27: 13.03
A28: 19 | C28: 17831 | D28: YLC-409 | E28: 六合一滤材 500g | F28: Six-in-one filter material 500g | G28: 0.97183099 | H28: 5 | I28: 4.86
A29: 20 | C29: C4-1067-1 | D29: C4-1067 | E29: 3W 油膜处理器 | F29: 3W oil film processor | G29: 2.61 | H29: 4 | I29: 10.44
A30: 21 | C30: 08116 | D30: LED-318 | E30: yee三色可调 3.5W 双排广角灯27cm | F30: Yee three-color adjustable 3.5W double-row wide-angle light, 27cm | G30: 0 | H30: 4 | I30: 0 | J30: Free gift
A31: 22 | C31: 07140 | D31: CLS-107 | E31: 鱼缸磁力刷 大号 蓝色强磁 | F31: Aquarium magnetic cleaning brush, large size, blue, strong magnet. | G31: 0 | H31: 3 | I31: 0 | J31: Free gift
A32: 23 | C32: 1.15.60 | D32: YEE-3656 | E32: 16mm牛筋管1.0米 | F32: 1.0 meter of 16mm reinforced plastic tubing | G32: 0 | H32: 5 | I32: 0 | J32: Free gift
A33: 24 | C33: 06255 | D33: =VLOOKUP(C33,[1]水草缸!$A:$C,3,0) -> YXL-003 | E33: 400x230x250mm 5mm厚 | F33: 400x230x250mm 5mm thick | G33: 6.2816901 | H33: 2 | I33: =G33*H33 -> 12.56338 | J33: 打木箱，大小号嵌套，内部塞其它产品
A34: 25 | C34: 05380 | D34: =VLOOKUP(C34,[1]水草缸!$A:$C,3,0) -> YKK-50 | E34: 500x270x300mm 5mm厚 | F34: 500x270x300mm 5mm thick | G34: 9.7323944 | H34: 2 | I34: =G34*H34 -> 19.464789
A35: 26 | C35: 05381 | D35: =VLOOKUP(C35,[1]水草缸!$A:$C,3,0) -> YKK-60 | E35: 600x300x350mm 5mm厚 | F35: 600x300x350mm 5mm thick | G35: 12.521127 | H35: 2 | I35: =G35*H35 -> 25.042254
A36: 27 | C36: 16932 | D36: =VLOOKUP(C36,[1]水草缸!$A:$C,3,0) -> YEE-1090 | E36: 35×35×35 6mm 厚 | F36: 35×35×35 6mm thick | G36: 8.5915493 | H36: 2 | I36: =G36*H36 -> 17.183099 | J36: 打木箱，大小号嵌套，内部塞其它产品
A37: 28 | C37: 05662 | D37: =VLOOKUP(C37,[1]水草缸!$A:$C,3,0) -> YCG-40 | E37: 40X40X40cm 6mm厚 | F37: 40X40X40cm 6mm thick | G37: 11.549296 | H37: 2 | I37: =G37*H37 -> 23.098592
A38: 29 | C38: C5-1062-1 | D38: =VLOOKUP(C38,[1]水草缸!$A:$C,3,0) -> C5-1062 | E38: 60*40*40cm 8mm | F38: 60*40*40cm 8mm | G38: 18.169014 | H38: 2 | I38: =G38*H38 -> 36.338028 | J38: 打木箱，内部塞其它产品
A39: 30 | C39: C5-1123-2 | D39: C5-1123 | E39: 裸缸侧虑溪流缸60*15*15cm 6mm送水泵 | F39: Bare side stream tank 60*15*15cm 6mm water pump | G39: 17.295775 | H39: 2 | I39: =G39*H39 -> 34.591549 | J39: 打木箱，内部塞其它产品
A40: Products price | I40: =SUM(I10:I39) -> 440.68507
...
