Workbook

Sheet Sheet1
A1: Weifang Yipin Pet Articles Co.,Ltd
A2: ADD: R 301Q, Building 1, Shengshi Haoting Huijingyuan, No. 1999 Wenhua Road, Kuiwen District, Weifang City, Shandong Province,China
A3: yeeaquarium@chongujia.com
A4: INVOICE
A5: Pickup Info | G5: Order Info
A6: EXW 客户自提 收货地址add：山东省潍坊市坊子区北海路翠坊街交叉口西行1000米汉唐电动汽车西门进 预估体积（Estimated total volume）: 1.5 cbm 预估重量（Estimated total weight）: 440 kg | G6: Invoice No.: 2512271150 Invoice Date: 2025-12-29 Sales Rep: Tina Tong
C7: Shipping Term: | F7: PI NO.:
A8: Item No. | B8: Picture | C8: Business Code | D8: Model | E8: Chinese Name | F8: English Name | G8: Price | H8: QTY | I8: Amount | J8: Remark
G9: （USD） | H9: (PCS) | I9: （USD）
A10: 1 | C10: C1-1113-2 | D10: C1-1113 | E10: Yee小型鱼配合饲料全效合一0.6mm75g | F10: Yee Small Fish Feed All-in-One 0.6mm 75g | G10: 0.63 | H10: 25 | I10: 15.75
A11: 2 | C11: C1-1127-1 | D11: C1-1127 | E11: 金鱼兰寿善玉菌+螺旋藻色扬配合饲料290g缓沉3.0mm | F11: Goldfish Orchid Longevity Jade Fungus + Spirulina Color Yang Compound Feed 290g Slow Sinking 3.0mm | G11: 1.8 | H11: 15 | I11: 27
A12: 3 | C12: C1-1073-1a | D12: C1-1073 | E12: Yee斗鱼配合饲料0.8mm130g新更换条码 | F12: Betta fish food 0.8mm 130g New | G12: 0.97 | H12: 20 | I12: 19.4
A13: 4 | C13: C1-1082-5 | D13: C1-1082 | E13: Imitation red worm feed 0.5mm 115g | F13: Imitation red worm feed 0.5mm 115g | G13: 1.35 | H13: 30 | I13: 40.5
A14: 5 | C14: C1-1065-1 | D14: C1-1065 | E14: Yee蝴蝶鲤配合饲料1.5mm300g袋装 | F14: Floating Grain - Competition Grade 45% High Protein [1.5mm Small Particles] 300g Bag | G14: 0.86 | H14: 1 | I14: 0.86
A15: 6 | C15: C1-1066-2 | D15: C1-1066 | E15: Yee水族观赏虾专用粮260g | F15: 【40% High Protein】Special Food for Ornamental Shrimp 260g | G15: 1.7 | H15: 1 | I15: 1.7
A16: 7 | C16: 03446a | D16: YYY-078 | E16: 新款脱壳卵(80g150ml)白瓶+喂食器SJ | F16: New Shelled Eggs (80g 150ml) White Bottle + Feeder | G16: 1.65 | H16: 1 | I16: 1.65
A17: 8 | C17: C1-1125-1 | D17: C1-1125 | E17: Yee水族-寄居蟹冻干盛宴55g55g | F17: Yee Aqua-Hermit Crab Freeze-Dried Feast 55g | G17: 1.27 | H17: 1 | I17: 1.27
A18: 9 | C18: C1-1069-1 | D18: C1-1069 | E18: 鱼粮连包铜版纸吊卡DJ | F18: Fish feed with coated paper hanger | G18: 0.62 | H18: 15 | I18: 9.3
A19: 10 | C19: C1-1082-2a | D19: C1-1082 | E19: Yee小型鱼配合饲料全效合一0.2mm210g更换条码 | F19: 【All-in-one】Microparticles/0.2mm/210g | G19: 1.04 | H19: 10 | I19: 10.4
A20: 11 | C20: C1-1134-6 | D20: C1-1134 | E20: 金鱼兰寿配合饲料1.5mm下沉500g袋装 | F20: Ranchu goldfish formulated feed, 1.5mm diameter, sinks 500g per bag. | G20: 1.69 | H20: 12 | I20: 20.28
A21: 12 | C21: C1-1086-1 | D21: C1-1086 | E21: Yee水族冻干丰年虾块18g | F21: Yee Aquarium Freeze-dried Brine Shrimp Chunks 18g 225ml | G21: 0.9 | H21: 8 | I21: 7.2
A22: 13 | C22: C1-1124-1 | D22: C1-1124 | E22: Yee意牌水族三合一斗鱼配合饲料15g | F22: Yee Brand 3-in-1 Betta Fish Food 15g | G22: 0.48 | H22: 10 | I22: 4.8
A23: 14 | C23: 12420 | D23: YYH-125 | E23: 白点净300ml | F23: White Spot Cleaner 300ml | G23: 0.71830986 | H23: 10 | I23: 7.18
A24: 15 | C24: 19768a | D24: YYH-207 | E24: 亚甲基蓝溶液 600ml | F24: Methylene blue solution 600ml | G24: 0.93 | H24: 8 | I24: 7.44
A25: 16 | C25: 02856a | D25: YYH-006 | E25: 杀菌/抑菌/速溶粉末2g/袋×10袋[1盒] | F25: Bactericidal/antibacterial/instant powder 2g/bag × 10 bags [1 box] | G25: 1.13 | H25: 6 | I25: 6.78
A26: 17 | C26: c2-1016-2 | D26: c2-1016 | E26: Yee意牌水族净氨系列活性益生菌760ml | F26: Yee Aquarium Cleansing Ammonia Series Active Probiotics 760ml | G26: 2.34 | H26: 10 | I26: 23.4
A27: 18 | C27: c2-1016-1a | D27: c2-1016 | E27: Yee意牌水族净氨系列活性益生菌400ml | F27: Yee Aquarium Cleansing Ammonia Series Active Probiotics 400ml | G27: 1.38 | H27: 5 | I27: 6.9
A28: 19 | C28: 02924 | D28: YYH-039 | E28: yee蓝色经典-除氯水质稳定剂535ml | F28: Yee Blue Classic-Chlorine Removal Water Stabilizer 535ml | G28: 0.72 | H28: 15 | I28: 10.8
A29: 20 | C29: 16940 | D29: YYH-173 | E29: 抗应激水质稳定剂 500ml 新风格 | F29: Anti-stress water stabilizer 500ml New style | G29: 0.91549296 | H29: 8 | I29: 7.32
A30: 21 | C30: C3-1010-3 | D30: C3-1010 | E30: 【氨氮测试剂】可测约60次/精准快速 | F30: 【Ammonia nitrogen tester】can test about 60 times/accurate and fast | G30: 2.87 | H30: 8 | I30: 22.96
A31: 22 | C31: C3-1010-1 | D31: C3-1010 | E31: 【亚硝酸盐测试剂】可测约100次/精准快速 | F31: 【Nitrite test kit】can test about 100 times/accurate and fast | G31: 2.87 | H31: 8 | I31: 22.96
A32: 23 | C32: C4-1123-1a | D32: C4-1123 | E32: 【新手级50条】9合1/桶装/带对比表 | F32: [Novice Level 50] 9-in-1/Bucket/With Comparison Chart | G32: 1.62 | H32: 10 | I32: 16.2
A33: 24 | C33: C2-1005-1 | D33: C2-1005 | E33: Yee意牌水族硝化菌+益生菌胶囊50粒 | F33: Yee Aquarium Nitrifying Bacteria + Probiotics Capsules 50 capsules | G33: 0.85 | H33: 12 | I33: 10.2
A34: 25 | C34: C2-1005-2 | D34: C2-1005 | E34: Yee意牌水族硝化菌+益生菌胶囊100粒 | F34: Yee Aquarium Nitrifying Bacteria + Probiotics Capsules 100 Capsules | G34: 1.27 | H34: 8 | I34: 10.16
A35: 26 | C35: 19429 | D35: YYH-189 | E35: 除藻剂 500ml 新风格 | F35: Algaecide 500ml New Style | G35: 0.91549296 | H35: 10 | I35: 9.15
A36: 27 | C36: 19939 | D36: YYH-216 | E36: 抗应激水质稳定剂 1000ml 新风格 | F36: Anti-stress water stabilizer 1000ml New style | G36: 1.1267606 | H36: 6 | I36: 6.76
A37: 28 | C37: 06834 | D37: YAN-804 | E37: 多维矿物盐500克 | F37: Multivitamin mineral salt 500g | G37: 0.2 | H37: 10 | I37: 2
A38: 29 | C38: 01831 | D38: YAN-915 | E38: 500G多维盐盒装YAN-915 | F38: 500G Multivitamin Salt Box YAN-915 | G38: 0.87 | H38: 5 | I38: 4.35
A39: 30 | C39: 02938a | D39: YYH-053 | E39: yee蓝色经典-亚甲基蓝溶液235ml | F39: Yee Blue Classic-Methylene Blue Solution 235ml | G39: 0.45 | H39: 10 | I39: 4.5
A40: 31 | C40: C4-1123-2a | D40: C4-1123 | E40: 【补充装】9合1/补充装/50条 | F40: 【Refill】9 in 1/Refill/50 pieces | G40: 1.06 | H40: 10 | I40: =G40*H40 -> 10.6
...
